2025-01-03 18:06:40,740 INFO    MainThread:2758849 [wandb_setup.py:_flush():79] Current SDK version is 0.18.7
2025-01-03 18:06:40,740 INFO    MainThread:2758849 [wandb_setup.py:_flush():79] Configure stats pid to 2758849
2025-01-03 18:06:40,740 INFO    MainThread:2758849 [wandb_setup.py:_flush():79] Loading settings from /mnt/zhaorunsong/.config/wandb/settings
2025-01-03 18:06:40,740 INFO    MainThread:2758849 [wandb_setup.py:_flush():79] Loading settings from /mnt/zhaorunsong/repository/ReCMLLM/wandb/settings
2025-01-03 18:06:40,740 INFO    MainThread:2758849 [wandb_setup.py:_flush():79] Loading settings from environment variables: {}
2025-01-03 18:06:40,740 INFO    MainThread:2758849 [wandb_setup.py:_flush():79] Applying setup settings: {'mode': None, '_disable_service': None}
2025-01-03 18:06:40,740 INFO    MainThread:2758849 [wandb_setup.py:_flush():79] Inferring run settings from compute environment: {'program_relpath': 'train.py', 'program_abspath': '/mnt/zhaorunsong/repository/ReCMLLM/train.py', 'program': '/mnt/zhaorunsong/repository/ReCMLLM/train.py'}
2025-01-03 18:06:40,740 INFO    MainThread:2758849 [wandb_setup.py:_flush():79] Applying login settings: {}
2025-01-03 18:06:40,740 INFO    MainThread:2758849 [wandb_init.py:_log_setup():533] Logging user logs to /mnt/zhaorunsong/repository/ReCMLLM/wandb/run-20250103_180640-dbu5kz9v/logs/debug.log
2025-01-03 18:06:40,740 INFO    MainThread:2758849 [wandb_init.py:_log_setup():534] Logging internal logs to /mnt/zhaorunsong/repository/ReCMLLM/wandb/run-20250103_180640-dbu5kz9v/logs/debug-internal.log
2025-01-03 18:06:40,740 INFO    MainThread:2758849 [wandb_init.py:init():619] calling init triggers
2025-01-03 18:06:40,740 INFO    MainThread:2758849 [wandb_init.py:init():626] wandb.init called with sweep_config: {}
config: {}
2025-01-03 18:06:40,740 INFO    MainThread:2758849 [wandb_init.py:init():669] starting backend
2025-01-03 18:06:40,740 INFO    MainThread:2758849 [wandb_init.py:init():673] sending inform_init request
2025-01-03 18:06:40,742 INFO    MainThread:2758849 [backend.py:_multiprocessing_setup():104] multiprocessing start_methods=fork,spawn,forkserver, using: spawn
2025-01-03 18:06:40,743 INFO    MainThread:2758849 [wandb_init.py:init():686] backend started and connected
2025-01-03 18:06:40,746 INFO    MainThread:2758849 [wandb_init.py:init():781] updated telemetry
2025-01-03 18:06:40,754 INFO    MainThread:2758849 [wandb_init.py:init():814] communicating run to backend with 90.0 second timeout
2025-01-03 18:07:38,966 INFO    Thread-1 (wrapped_target):2758849 [retry.py:__call__():172] Retry attempt failed:
Traceback (most recent call last):
  File "/mnt/zhaorunsong/anaconda3/envs/ReCMLLM/lib/python3.10/site-packages/urllib3/connection.py", line 199, in _new_conn
    sock = connection.create_connection(
  File "/mnt/zhaorunsong/anaconda3/envs/ReCMLLM/lib/python3.10/site-packages/urllib3/util/connection.py", line 85, in create_connection
    raise err
  File "/mnt/zhaorunsong/anaconda3/envs/ReCMLLM/lib/python3.10/site-packages/urllib3/util/connection.py", line 73, in create_connection
    sock.connect(sa)
TimeoutError: timed out

The above exception was the direct cause of the following exception:

Traceback (most recent call last):
  File "/mnt/zhaorunsong/anaconda3/envs/ReCMLLM/lib/python3.10/site-packages/urllib3/connectionpool.py", line 789, in urlopen
    response = self._make_request(
  File "/mnt/zhaorunsong/anaconda3/envs/ReCMLLM/lib/python3.10/site-packages/urllib3/connectionpool.py", line 490, in _make_request
    raise new_e
  File "/mnt/zhaorunsong/anaconda3/envs/ReCMLLM/lib/python3.10/site-packages/urllib3/connectionpool.py", line 466, in _make_request
    self._validate_conn(conn)
  File "/mnt/zhaorunsong/anaconda3/envs/ReCMLLM/lib/python3.10/site-packages/urllib3/connectionpool.py", line 1095, in _validate_conn
    conn.connect()
  File "/mnt/zhaorunsong/anaconda3/envs/ReCMLLM/lib/python3.10/site-packages/urllib3/connection.py", line 693, in connect
    self.sock = sock = self._new_conn()
  File "/mnt/zhaorunsong/anaconda3/envs/ReCMLLM/lib/python3.10/site-packages/urllib3/connection.py", line 208, in _new_conn
    raise ConnectTimeoutError(
urllib3.exceptions.ConnectTimeoutError: (<urllib3.connection.HTTPSConnection object at 0x75e4b0bab400>, 'Connection to api.wandb.ai timed out. (connect timeout=20)')

The above exception was the direct cause of the following exception:

Traceback (most recent call last):
  File "/mnt/zhaorunsong/anaconda3/envs/ReCMLLM/lib/python3.10/site-packages/requests/adapters.py", line 667, in send
    resp = conn.urlopen(
  File "/mnt/zhaorunsong/anaconda3/envs/ReCMLLM/lib/python3.10/site-packages/urllib3/connectionpool.py", line 843, in urlopen
    retries = retries.increment(
  File "/mnt/zhaorunsong/anaconda3/envs/ReCMLLM/lib/python3.10/site-packages/urllib3/util/retry.py", line 519, in increment
    raise MaxRetryError(_pool, url, reason) from reason  # type: ignore[arg-type]
urllib3.exceptions.MaxRetryError: HTTPSConnectionPool(host='api.wandb.ai', port=443): Max retries exceeded with url: /graphql (Caused by ConnectTimeoutError(<urllib3.connection.HTTPSConnection object at 0x75e4b0bab400>, 'Connection to api.wandb.ai timed out. (connect timeout=20)'))

During handling of the above exception, another exception occurred:

Traceback (most recent call last):
  File "/mnt/zhaorunsong/anaconda3/envs/ReCMLLM/lib/python3.10/site-packages/wandb/sdk/lib/retry.py", line 131, in __call__
    result = self._call_fn(*args, **kwargs)
  File "/mnt/zhaorunsong/anaconda3/envs/ReCMLLM/lib/python3.10/site-packages/wandb/sdk/internal/internal_api.py", line 400, in execute
    return self.client.execute(*args, **kwargs)  # type: ignore
  File "/mnt/zhaorunsong/anaconda3/envs/ReCMLLM/lib/python3.10/site-packages/wandb/vendor/gql-0.2.0/wandb_gql/client.py", line 52, in execute
    result = self._get_result(document, *args, **kwargs)
  File "/mnt/zhaorunsong/anaconda3/envs/ReCMLLM/lib/python3.10/site-packages/wandb/vendor/gql-0.2.0/wandb_gql/client.py", line 60, in _get_result
    return self.transport.execute(document, *args, **kwargs)
  File "/mnt/zhaorunsong/anaconda3/envs/ReCMLLM/lib/python3.10/site-packages/wandb/sdk/lib/gql_request.py", line 58, in execute
    request = self.session.post(self.url, **post_args)
  File "/mnt/zhaorunsong/anaconda3/envs/ReCMLLM/lib/python3.10/site-packages/requests/sessions.py", line 637, in post
    return self.request("POST", url, data=data, json=json, **kwargs)
  File "/mnt/zhaorunsong/anaconda3/envs/ReCMLLM/lib/python3.10/site-packages/requests/sessions.py", line 589, in request
    resp = self.send(prep, **send_kwargs)
  File "/mnt/zhaorunsong/anaconda3/envs/ReCMLLM/lib/python3.10/site-packages/requests/sessions.py", line 703, in send
    r = adapter.send(request, **kwargs)
  File "/mnt/zhaorunsong/anaconda3/envs/ReCMLLM/lib/python3.10/site-packages/requests/adapters.py", line 688, in send
    raise ConnectTimeout(e, request=request)
requests.exceptions.ConnectTimeout: HTTPSConnectionPool(host='api.wandb.ai', port=443): Max retries exceeded with url: /graphql (Caused by ConnectTimeoutError(<urllib3.connection.HTTPSConnection object at 0x75e4b0bab400>, 'Connection to api.wandb.ai timed out. (connect timeout=20)'))
2025-01-03 18:08:00,457 WARNING MainThread:2758849 [wandb_init.py:init():1260] interrupted
Traceback (most recent call last):
  File "/mnt/zhaorunsong/anaconda3/envs/ReCMLLM/lib/python3.10/site-packages/wandb/sdk/wandb_init.py", line 1256, in init
    return wi.init()
  File "/mnt/zhaorunsong/anaconda3/envs/ReCMLLM/lib/python3.10/site-packages/wandb/sdk/wandb_init.py", line 817, in init
    result = run_init_handle.wait(
  File "/mnt/zhaorunsong/anaconda3/envs/ReCMLLM/lib/python3.10/site-packages/wandb/sdk/lib/mailbox.py", line 279, in wait
    found, abandoned = self._slot._get_and_clear(timeout=wait_timeout)
  File "/mnt/zhaorunsong/anaconda3/envs/ReCMLLM/lib/python3.10/site-packages/wandb/sdk/lib/mailbox.py", line 126, in _get_and_clear
    if self._wait(timeout=timeout):
  File "/mnt/zhaorunsong/anaconda3/envs/ReCMLLM/lib/python3.10/site-packages/wandb/sdk/lib/mailbox.py", line 122, in _wait
    return self._event.wait(timeout=timeout)
  File "/mnt/zhaorunsong/anaconda3/envs/ReCMLLM/lib/python3.10/threading.py", line 600, in wait
    signaled = self._cond.wait(timeout)
  File "/mnt/zhaorunsong/anaconda3/envs/ReCMLLM/lib/python3.10/threading.py", line 324, in wait
    gotit = waiter.acquire(True, timeout)
KeyboardInterrupt
2025-01-03 18:08:00,764 WARNING MsgRouterThr:2758849 [router.py:message_loop():75] message_loop has been closed
